python3: can't open file 'MyScheduledProgram.py': [Errno 2] No such file or directory
Traceback (most recent call last):
  File "test.py", line 31, in <module>
    schedule.every().day.at("16:50").do(collect_data())
  File "/home/dannguyen/.local/lib/python3.6/site-packages/schedule/__init__.py", line 440, in do
    self.job_func = functools.partial(job_func, *args, **kwargs)
TypeError: the first argument must be callable
Traceback (most recent call last):
  File "test.py", line 31, in <module>
    schedule.every().day.at("16:59").do(collect_data())
  File "/home/dannguyen/.local/lib/python3.6/site-packages/schedule/__init__.py", line 440, in do
    self.job_func = functools.partial(job_func, *args, **kwargs)
TypeError: the first argument must be callable
